Workbook
Name sel_Region: Dashboard!$B$6
Name sel_Country: Dashboard!$D$6
Name sel_Channel: Dashboard!$F$6
Name sel_Customer: Dashboard!$H$6
Name sel_Category: Dashboard!$J$6
Name sel_Product: Dashboard!$L$6
Name sel_FromMonth: Dashboard!$N$6
Name sel_ToMonth: Dashboard!$P$6
Name m_From: Analysis!$C$4
Name m_To: Analysis!$C$5

Sheet Dashboard
B2: SALES PERFORMANCE DASHBOARD | FY2026 | L2: Dashboard | N2: Analysis | P2: Data | R2: Guide
B3: =IF(Analysis!$C$6<>"OK","WARNING: "&Analysis!$C$6,N6&"-"&P6&" | Region: "&B6&" | Country: "&D6&" | Channel: "&F6&" | Customer: "&H6&" | Category: "&J6&" | Product: "&L6)
B5: REGION | D5: COUNTRY | F5: SALES CHANNEL | H5: CUSTOMER TYPE | J5: CATEGORY | L5: PRODUCT | N5: FROM MONTH | P5: TO MONTH | R5: ORDERS SHOWN
B6: All | D6: All | F6: All | H6: All | J6: All | L6: All | N6: Jan | P6: Dec | R6: =Analysis!$C$13
B8: TOTAL REVENUE | E8: GROSS PROFIT | H8: GROSS MARGIN | K8: UNITS SOLD | N8: AVG ORDER VALUE | Q8: AVG UNIT PRICE
B9: =Analysis!$C$9 | E9: =Analysis!$C$10 | H9: =Analysis!$C$11 | K9: =Analysis!$C$12 | N9: =Analysis!$C$14 | Q9: =Analysis!$C$15
B11: =TEXT(Analysis!$C$18,"0.0%")&" of full-year revenue" | E11: ="Margin "&TEXT(Analysis!$C$11,"0.0%") | H11: ="Profit as % of revenue" | K11: =TEXT(Analysis!$C$13,"#,##0")&" orders" | N11: ="Revenue per order" | Q11: ="Net revenue per unit"
B13: TOP COUNTRY | E13: BEST MONTH | H13: TOP CATEGORY | K13: TOP CHANNEL | N13: TOP CUSTOMER TYPE | Q13: TOP PRODUCT
B14: =Analysis!$H$4 | E14: =Analysis!$H$5 | H14: =Analysis!$H$6 | K14: =Analysis!$H$7 | N14: =Analysis!$H$8 | Q14: =Analysis!$H$9
B16: Monthly Revenue & Gross Profit | L16: Revenue by Product Category
B35: Revenue Map of Europe (tile map) | L35: Top 5 Bestselling Products (units)
D37: Norway | F37: Sweden | H37: Finland
D38: =INDEX(Analysis!$C$63:$C$79,MATCH("Norway",Analysis!$B$63:$B$79,0)) | F38: =INDEX(Analysis!$C$63:$C$79,MATCH("Sweden",Analysis!$B$63:$B$79,0)) | H38: =INDEX(Analysis!$C$63:$C$79,MATCH("Finland",Analysis!$B$63:$B$79,0))
B39: Ireland | D39: United Kingdom | F39: Denmark
B40: =INDEX(Analysis!$C$63:$C$79,MATCH("Ireland",Analysis!$B$63:$B$79,0)) | D40: =INDEX(Analysis!$C$63:$C$79,MATCH("United Kingdom",Analysis!$B$63:$B$79,0)) | F40: =INDEX(Analysis!$C$63:$C$79,MATCH("Denmark",Analysis!$B$63:$B$79,0))
D41: Netherlands | F41: Germany | H41: Poland
D42: =INDEX(Analysis!$C$63:$C$79,MATCH("Netherlands",Analysis!$B$63:$B$79,0)) | F42: =INDEX(Analysis!$C$63:$C$79,MATCH("Germany",Analysis!$B$63:$B$79,0)) | H42: =INDEX(Analysis!$C$63:$C$79,MATCH("Poland",Analysis!$B$63:$B$79,0))
B43: Belgium | D43: France | F43: Switzerland | H43: Austria | J43: Czechia
B44: =INDEX(Analysis!$C$63:$C$79,MATCH("Belgium",Analysis!$B$63:$B$79,0)) | D44: =INDEX(Analysis!$C$63:$C$79,MATCH("France",Analysis!$B$63:$B$79,0)) | F44: =INDEX(Analysis!$C$63:$C$79,MATCH("Switzerland",Analysis!$B$63:$B$79,0)) | H44: =INDEX(Analysis!$C$63:$C$79,MATCH("Austria",Analysis!$B$63:$B$79,0)) | J44: =INDEX(Analysis!$C$63:$C$79,MATCH("Czechia",Analysis!$B$63:$B$79,0))
B45: Portugal | D45: Spain | F45: Italy
B46: =INDEX(Analysis!$C$63:$C$79,MATCH("Portugal",Analysis!$B$63:$B$79,0)) | D46: =INDEX(Analysis!$C$63:$C$79,MATCH("Spain",Analysis!$B$63:$B$79,0)) | F46: =INDEX(Analysis!$C$63:$C$79,MATCH("Italy",Analysis!$B$63:$B$79,0))
B48: Tiles sit roughly where each country is on the map. Shade = revenue (light = low, dark = high). The selected country gets an orange label. With the macro installed, click a tile to filter the whole dashboard.
B54: Top 10 Countries by Revenue | L54: Revenue Mix
L55: BY SALES CHANNEL | P55: BY CUSTOMER TYPE

Sheet Analysis
B1: Analysis (calculation layer behind the dashboard) | K1: Dashboard | M1: Analysis | O1: Data | Q1: Guide
B3: Filter helpers | G3: Highlights (respect all filters)
B4: From month (number) | C4: =MATCH(sel_FromMonth,Lists!$D$4:$D$15,0) | G4: Top country | H4: =IF($C$9=0,"-",INDEX($B$63:$B$79,MATCH(MAX($D$63:$D$79),$D$63:$D$79,0))&" ($"&TEXT(MAX($D$63:$D$79)/1000,"#,##0.0")&"K)")
B5: To month (number) | C5: =MATCH(sel_ToMonth,Lists!$D$4:$D$15,0) | G5: Best month | H5: =IF($C$9=0,"-",INDEX($B$23:$B$34,MATCH(MAX($E$23:$E$34),$E$23:$E$34,0))&" ($"&TEXT(MAX($E$23:$E$34)/1000,"#,##0.0")&"K)")
B6: Valid month range? | C6: =IF(C4<=C5,"OK","From month is after To month - nothing shown") | G6: Top category | H6: =IF($C$9=0,"-",INDEX($B$39:$B$43,MATCH(MAX($D$39:$D$43),$D$39:$D$43,0))&" ($"&TEXT(MAX($D$39:$D$43)/1000,"#,##0.0")&"K)")
G7: Top sales channel | H7: =IF($C$9=0,"-",INDEX($B$48:$B$51,MATCH(MAX($D$48:$D$51),$D$48:$D$51,0))&" ($"&TEXT(MAX($D$48:$D$51)/1000,"#,##0.0")&"K)")
B8: KPIs (respect all filters) | G8: Top customer type | H8: =IF($C$9=0,"-",INDEX($B$56:$B$58,MATCH(MAX($D$56:$D$58),$D$56:$D$58,0))&" ($"&TEXT(MAX($D$56:$D$58)/1000,"#,##0.0")&"K)")
B9: Revenue | C9: =SUMIFS(Data!$M$4:$M$2710,Data!$U$4:$U$2710,1) | G9: Top product (units) | H9: =IF($C$9=0,"-",INDEX($B$84:$B$103,MATCH(MAX($D$84:$D$103),$D$84:$D$103,0))&" ("&MAX($D$84:$D$103)&" units)")
B10: Gross Profit | C10: =SUMIFS(Data!$O$4:$O$2710,Data!$U$4:$U$2710,1)
B11: Gross Margin % | C11: =IF(C9=0,0,C10/C9)
B12: Units Sold | C12: =SUMIFS(Data!$I$4:$I$2710,Data!$U$4:$U$2710,1)
B13: Orders | C13: =COUNTIFS(Data!$U$4:$U$2710,1)
B14: Avg Order Value | C14: =IF(C13=0,0,C9/C13)
B15: Avg Unit Price (net) | C15: =IF(C12=0,0,C9/C12)
B16: Total Revenue (no filter) | C16: =SUM(Data!$M$4:$M$2710)
B17: Total Gross Profit (no filter) | C17: =SUM(Data!$O$4:$O$2710)
B18: Revenue share of total | C18: =IF(C16=0,0,C9/C16)
B21: Monthly trend (shows all months; months outside the From-To range are greyed)
B22: Month | C22: Revenue | D22: Gross Profit | E22: Revenue (selected months) | F22: Excluded months
B23: =Lists!$D$4 | C23: =SUMIFS(Data!$M$4:$M$2710,Data!$AA$4:$AA$2710,1,Data!$S$4:$S$2710,1) | D23: =SUMIFS(Data!$O$4:$O$2710,Data!$AA$4:$AA$2710,1,Data!$S$4:$S$2710,1) | E23: =IF(AND(1>=m_From,1<=m_To),C23,0) | F23: =C23-E23
B24: =Lists!$D$5 | C24: =SUMIFS(Data!$M$4:$M$2710,Data!$AA$4:$AA$2710,1,Data!$S$4:$S$2710,2) | D24: =SUMIFS(Data!$O$4:$O$2710,Data!$AA$4:$AA$2710,1,Data!$S$4:$S$2710,2) | E24: =IF(AND(2>=m_From,2<=m_To),C24,0) | F24: =C24-E24
B25: =Lists!$D$6 | C25: =SUMIFS(Data!$M$4:$M$2710,Data!$AA$4:$AA$2710,1,Data!$S$4:$S$2710,3) | D25: =SUMIFS(Data!$O$4:$O$2710,Data!$AA$4:$AA$2710,1,Data!$S$4:$S$2710,3) | E25: =IF(AND(3>=m_From,3<=m_To),C25,0) | F25: =C25-E25
B26: =Lists!$D$7 | C26: =SUMIFS(Data!$M$4:$M$2710,Data!$AA$4:$AA$2710,1,Data!$S$4:$S$2710,4) | D26: =SUMIFS(Data!$O$4:$O$2710,Data!$AA$4:$AA$2710,1,Data!$S$4:$S$2710,4) | E26: =IF(AND(4>=m_From,4<=m_To),C26,0) | F26: =C26-E26
B27: =Lists!$D$8 | C27: =SUMIFS(Data!$M$4:$M$2710,Data!$AA$4:$AA$2710,1,Data!$S$4:$S$2710,5) | D27: =SUMIFS(Data!$O$4:$O$2710,Data!$AA$4:$AA$2710,1,Data!$S$4:$S$2710,5) | E27: =IF(AND(5>=m_From,5<=m_To),C27,0) | F27: =C27-E27
B28: =Lists!$D$9 | C28: =SUMIFS(Data!$M$4:$M$2710,Data!$AA$4:$AA$2710,1,Data!$S$4:$S$2710,6) | D28: =SUMIFS(Data!$O$4:$O$2710,Data!$AA$4:$AA$2710,1,Data!$S$4:$S$2710,6) | E28: =IF(AND(6>=m_From,6<=m_To),C28,0) | F28: =C28-E28
B29: =Lists!$D$10 | C29: =SUMIFS(Data!$M$4:$M$2710,Data!$AA$4:$AA$2710,1,Data!$S$4:$S$2710,7) | D29: =SUMIFS(Data!$O$4:$O$2710,Data!$AA$4:$AA$2710,1,Data!$S$4:$S$2710,7) | E29: =IF(AND(7>=m_From,7<=m_To),C29,0) | F29: =C29-E29
B30: =Lists!$D$11 | C30: =SUMIFS(Data!$M$4:$M$2710,Data!$AA$4:$AA$2710,1,Data!$S$4:$S$2710,8) | D30: =SUMIFS(Data!$O$4:$O$2710,Data!$AA$4:$AA$2710,1,Data!$S$4:$S$2710,8) | E30: =IF(AND(8>=m_From,8<=m_To),C30,0) | F30: =C30-E30
B31: =Lists!$D$12 | C31: =SUMIFS(Data!$M$4:$M$2710,Data!$AA$4:$AA$2710,1,Data!$S$4:$S$2710,9) | D31: =SUMIFS(Data!$O$4:$O$2710,Data!$AA$4:$AA$2710,1,Data!$S$4:$S$2710,9) | E31: =IF(AND(9>=m_From,9<=m_To),C31,0) | F31: =C31-E31
B32: =Lists!$D$13 | C32: =SUMIFS(Data!$M$4:$M$2710,Data!$AA$4:$AA$2710,1,Data!$S$4:$S$2710,10) | D32: =SUMIFS(Data!$O$4:$O$2710,Data!$AA$4:$AA$2710,1,Data!$S$4:$S$2710,10) | E32: =IF(AND(10>=m_From,10<=m_To),C32,0) | F32: =C32-E32
B33: =Lists!$D$14 | C33: =SUMIFS(Data!$M$4:$M$2710,Data!$AA$4:$AA$2710,1,Data!$S$4:$S$2710,11) | D33: =SUMIFS(Data!$O$4:$O$2710,Data!$AA$4:$AA$2710,1,Data!$S$4:$S$2710,11) | E33: =IF(AND(11>=m_From,11<=m_To),C33,0) | F33: =C33-E33
B34: =Lists!$D$15 | C34: =SUMIFS(Data!$M$4:$M$2710,Data!$AA$4:$AA$2710,1,Data!$S$4:$S$2710,12) | D34: =SUMIFS(Data!$O$4:$O$2710,Data!$AA$4:$AA$2710,1,Data!$S$4:$S$2710,12) | E34: =IF(AND(12>=m_From,12<=m_To),C34,0) | F34: =C34-E34
B37: Revenue by Product Category
B38: Item | C38: Value (own filter ignored) | D38: Selected | E38: Rank key | G38: Sorted item | H38: Selected | I38: Excluded
B39: Camping | C39: =SUMIFS(Data!$M$4:$M$2710,Data!$Y$4:$Y$2710,1,Data!$G$4:$G$2710,B39) | D39: =IF(OR(sel_Category="All",B39=sel_Category),C39,0) | E39: =C39+ROW()/1000000 | G39: =IF(INDEX($C$39:$C$43,MATCH(LARGE($E$39:$E$43,1),$E$39:$E$43,0))=0,"",INDEX($B$39:$B$43,MATCH(LARGE($E$39:$E$43,1),$E$39:$E$43,0))) | H39: =INDEX($D$39:$D$43,MATCH(LARGE($E$39:$E$43,1),$E$39:$E$43,0)) | I39: =INDEX($C$39:$C$43,MATCH(LARGE($E$39:$E$43,1),$E$39:$E$43,0))-INDEX($D$39:$D$43,MATCH(LARGE($E$39:$E$43,1),$E$39:$E$43,0))
B40: Cycling | C40: =SUMIFS(Data!$M$4:$M$2710,Data!$Y$4:$Y$2710,1,Data!$G$4:$G$2710,B40) | D40: =IF(OR(sel_Category="All",B40=sel_Category),C40,0) | E40: =C40+ROW()/1000000 | G40: =IF(INDEX($C$39:$C$43,MATCH(LARGE($E$39:$E$43,2),$E$39:$E$43,0))=0,"",INDEX($B$39:$B$43,MATCH(LARGE($E$39:$E$43,2),$E$39:$E$43,0))) | H40: =INDEX($D$39:$D$43,MATCH(LARGE($E$39:$E$43,2),$E$39:$E$43,0)) | I40: =INDEX($C$39:$C$43,MATCH(LARGE($E$39:$E$43,2),$E$39:$E$43,0))-INDEX($D$39:$D$43,MATCH(LARGE($E$39:$E$43,2),$E$39:$E$43,0))
B41: Fitness | C41: =SUMIFS(Data!$M$4:$M$2710,Data!$Y$4:$Y$2710,1,Data!$G$4:$G$2710,B41) | D41: =IF(OR(sel_Category="All",B41=sel_Category),C41,0) | E41: =C41+ROW()/1000000 | G41: =IF(INDEX($C$39:$C$43,MATCH(LARGE($E$39:$E$43,3),$E$39:$E$43,0))=0,"",INDEX($B$39:$B$43,MATCH(LARGE($E$39:$E$43,3),$E$39:$E$43,0))) | H41: =INDEX($D$39:$D$43,MATCH(LARGE($E$39:$E$43,3),$E$39:$E$43,0)) | I41: =INDEX($C$39:$C$43,MATCH(LARGE($E$39:$E$43,3),$E$39:$E$43,0))-INDEX($D$39:$D$43,MATCH(LARGE($E$39:$E$43,3),$E$39:$E$43,0))
B42: Hiking | C42: =SUMIFS(Data!$M$4:$M$2710,Data!$Y$4:$Y$2710,1,Data!$G$4:$G$2710,B42) | D42: =IF(OR(sel_Category="All",B42=sel_Category),C42,0) | E42: =C42+ROW()/1000000 | G42: =IF(INDEX($C$39:$C$43,MATCH(LARGE($E$39:$E$43,4),$E$39:$E$43,0))=0,"",INDEX($B$39:$B$43,MATCH(LARGE($E$39:$E$43,4),$E$39:$E$43,0))) | H42: =INDEX($D$39:$D$43,MATCH(LARGE($E$39:$E$43,4),$E$39:$E$43,0)) | I42: =INDEX($C$39:$C$43,MATCH(LARGE($E$39:$E$43,4),$E$39:$E$43,0))-INDEX($D$39:$D$43,MATCH(LARGE($E$39:$E$43,4),$E$39:$E$43,0))
B43: Travel | C43: =SUMIFS(Data!$M$4:$M$2710,Data!$Y$4:$Y$2710,1,Data!$G$4:$G$2710,B43) | D43: =IF(OR(sel_Category="All",B43=sel_Category),C43,0) | E43: =C43+ROW()/1000000 | G43: =IF(INDEX($C$39:$C$43,MATCH(LARGE($E$39:$E$43,5),$E$39:$E$43,0))=0,"",INDEX($B$39:$B$43,MATCH(LARGE($E$39:$E$43,5),$E$39:$E$43,0))) | H43: =INDEX($D$39:$D$43,MATCH(LARGE($E$39:$E$43,5),$E$39:$E$43,0)) | I43: =INDEX($C$39:$C$43,MATCH(LARGE($E$39:$E$43,5),$E$39:$E$43,0))-INDEX($D$39:$D$43,MATCH(LARGE($E$39:$E$43,5),$E$39:$E$43,0))
B46: Revenue by Sales Channel
B47: Item | C47: Value (own filter ignored) | D47: Selected | E47: Rank key | G47: Sorted item | H47: Selected | I47: Excluded
...

Sheet Data
A1: Sales Data | H1: Dashboard | J1: Analysis | L1: Data | N1: Guide
A3: ID | B3: Order Date | C3: Region | D3: Country | E3: Sales Channel | F3: Customer Type | G3: Product Category | H3: Product | I3: Units Sold | J3: Unit Price | K3: Discount % | L3: Unit Cost | M3: Revenue | N3: COGS | O3: Gross Profit | P3: Gross Margin % | Q3: Year | R3: Quarter | S3: MonthNo | T3: Month | U3: In Filter | V3: Flag excl. Country | W3: Flag excl. Channel | X3: Flag excl. Customer | Y3: Flag excl. Category | Z3: Flag excl. Product | AA3: Flag excl. Month
A4: 03392 | B4: 46023 | C4: Southern Europe | D4: Spain | E4: Online Store | F4: Returning | G4: Cycling | H4: Commuter Helmet | I4: 2 | J4: 82.06 | K4: 0 | L4: 42.94 | M4: =I4*J4*(1-K4) | N4: =I4*L4 | O4: =M4-N4 | P4: =IF(M4=0,0,O4/M4) | Q4: =YEAR(B4) | R4: ="Q"&ROUNDUP(MONTH(B4)/3,0) | S4: =MONTH(B4) | T4: =TEXT(B4,"mmm") | U4: =IF(AND(OR(sel_Region="All",C4=sel_Region),OR(sel_Country="All",D4=sel_Country),OR(sel_Channel="All",E4=sel_Channel),OR(sel_Customer="All",F4=sel_Customer),OR(sel_Category="All",G4=sel_Category),OR(sel_Product="All",H4=sel_Product),AND(S4>=m_From,S4<=m_To)),1,0) | V4: =IF(AND(OR(sel_Region="All",C4=sel_Region),OR(sel_Channel="All",E4=sel_Channel),OR(sel_Customer="All",F4=sel_Customer),OR(sel_Category="All",G4=sel_Category),OR(sel_Product="All",H4=sel_Product),AND(S4>=m_From,S4<=m_To)),1,0) | W4: =IF(AND(OR(sel_Region="All",C4=sel_Region),OR(sel_Country="All",D4=sel_Country),OR(sel_Customer="All",F4=sel_Customer),OR(sel_Category="All",G4=sel_Category),OR(sel_Product="All",H4=sel_Product),AND(S4>=m_From,S4<=m_To)),1,0) | X4: =IF(AND(OR(sel_Region="All",C4=sel_Region),OR(sel_Country="All",D4=sel_Country),OR(sel_Channel="All",E4=sel_Channel),OR(sel_Category="All",G4=sel_Category),OR(sel_Product="All",H4=sel_Product),AND(S4>=m_From,S4<=m_To)),1,0) | Y4: =IF(AND(OR(sel_Region="All",C4=sel_Region),OR(sel_Country="All",D4=sel_Country),OR(sel_Channel="All",E4=sel_Channel),OR(sel_Customer="All",F4=sel_Customer),OR(sel_Product="All",H4=sel_Product),AND(S4>=m_From,S4<=m_To)),1,0) | Z4: =IF(AND(OR(sel_Region="All",C4=sel_Region),OR(sel_Country="All",D4=sel_Country),OR(sel_Channel="All",E4=sel_Channel),OR(sel_Customer="All",F4=sel_Customer),OR(sel_Category="All",G4=sel_Category),AND(S4>=m_From,S4<=m_To)),1,0) | AA4: =IF(AND(OR(sel_Region="All",C4=sel_Region),OR(sel_Country="All",D4=sel_Country),OR(sel_Channel="All",E4=sel_Channel),OR(sel_Customer="All",F4=sel_Customer),OR(sel_Category="All",G4=sel_Category),OR(sel_Product="All",H4=sel_Product)),1,0)
A5: 04836 | B5: 46024 | C5: Central Europe | D5: Czechia | E5: Corporate | F5: Returning | G5: Hiking | H5: Hiking Daypack 20L | I5: 4 | J5: 94.18 | K5: 0.15 | L5: 45.03 | M5: =I5*J5*(1-K5) | N5: =I5*L5 | O5: =M5-N5 | P5: =IF(M5=0,0,O5/M5) | Q5: =YEAR(B5) | R5: ="Q"&ROUNDUP(MONTH(B5)/3,0) | S5: =MONTH(B5) | T5: =TEXT(B5,"mmm") | U5: =IF(AND(OR(sel_Region="All",C5=sel_Region),OR(sel_Country="All",D5=sel_Country),OR(sel_Channel="All",E5=sel_Channel),OR(sel_Customer="All",F5=sel_Customer),OR(sel_Category="All",G5=sel_Category),OR(sel_Product="All",H5=sel_Product),AND(S5>=m_From,S5<=m_To)),1,0) | V5: =IF(AND(OR(sel_Region="All",C5=sel_Region),OR(sel_Channel="All",E5=sel_Channel),OR(sel_Customer="All",F5=sel_Customer),OR(sel_Category="All",G5=sel_Category),OR(sel_Product="All",H5=sel_Product),AND(S5>=m_From,S5<=m_To)),1,0) | W5: =IF(AND(OR(sel_Region="All",C5=sel_Region),OR(sel_Country="All",D5=sel_Country),OR(sel_Customer="All",F5=sel_Customer),OR(sel_Category="All",G5=sel_Category),OR(sel_Product="All",H5=sel_Product),AND(S5>=m_From,S5<=m_To)),1,0) | X5: =IF(AND(OR(sel_Region="All",C5=sel_Region),OR(sel_Country="All",D5=sel_Country),OR(sel_Channel="All",E5=sel_Channel),OR(sel_Category="All",G5=sel_Category),OR(sel_Product="All",H5=sel_Product),AND(S5>=m_From,S5<=m_To)),1,0) | Y5: =IF(AND(OR(sel_Region="All",C5=sel_Region),OR(sel_Country="All",D5=sel_Country),OR(sel_Channel="All",E5=sel_Channel),OR(sel_Customer="All",F5=sel_Customer),OR(sel_Product="All",H5=sel_Product),AND(S5>=m_From,S5<=m_To)),1,0) | Z5: =IF(AND(OR(sel_Region="All",C5=sel_Region),OR(sel_Country="All",D5=sel_Country),OR(sel_Channel="All",E5=sel_Channel),OR(sel_Customer="All",F5=sel_Customer),OR(sel_Category="All",G5=sel_Category),AND(S5>=m_From,S5<=m_To)),1,0) | AA5: =IF(AND(OR(sel_Region="All",C5=sel_Region),OR(sel_Country="All",D5=sel_Country),OR(sel_Channel="All",E5=sel_Channel),OR(sel_Customer="All",F5=sel_Customer),OR(sel_Category="All",G5=sel_Category),OR(sel_Product="All",H5=sel_Product)),1,0)
A6: 00163 | B6: 46025 | C6: Northern Europe | D6: Sweden | E6: Online Store | F6: New | G6: Travel | H6: Insulated Bottle | I6: 2 | J6: 36.72 | K6: 0.05 | L6: 13.76 | M6: =I6*J6*(1-K6) | N6: =I6*L6 | O6: =M6-N6 | P6: =IF(M6=0,0,O6/M6) | Q6: =YEAR(B6) | R6: ="Q"&ROUNDUP(MONTH(B6)/3,0) | S6: =MONTH(B6) | T6: =TEXT(B6,"mmm") | U6: =IF(AND(OR(sel_Region="All",C6=sel_Region),OR(sel_Country="All",D6=sel_Country),OR(sel_Channel="All",E6=sel_Channel),OR(sel_Customer="All",F6=sel_Customer),OR(sel_Category="All",G6=sel_Category),OR(sel_Product="All",H6=sel_Product),AND(S6>=m_From,S6<=m_To)),1,0) | V6: =IF(AND(OR(sel_Region="All",C6=sel_Region),OR(sel_Channel="All",E6=sel_Channel),OR(sel_Customer="All",F6=sel_Customer),OR(sel_Category="All",G6=sel_Category),OR(sel_Product="All",H6=sel_Product),AND(S6>=m_From,S6<=m_To)),1,0) | W6: =IF(AND(OR(sel_Region="All",C6=sel_Region),OR(sel_Country="All",D6=sel_Country),OR(sel_Customer="All",F6=sel_Customer),OR(sel_Category="All",G6=sel_Category),OR(sel_Product="All",H6=sel_Product),AND(S6>=m_From,S6<=m_To)),1,0) | X6: =IF(AND(OR(sel_Region="All",C6=sel_Region),OR(sel_Country="All",D6=sel_Country),OR(sel_Channel="All",E6=sel_Channel),OR(sel_Category="All",G6=sel_Category),OR(sel_Product="All",H6=sel_Product),AND(S6>=m_From,S6<=m_To)),1,0) | Y6: =IF(AND(OR(sel_Region="All",C6=sel_Region),OR(sel_Country="All",D6=sel_Country),OR(sel_Channel="All",E6=sel_Channel),OR(sel_Customer="All",F6=sel_Customer),OR(sel_Product="All",H6=sel_Product),AND(S6>=m_From,S6<=m_To)),1,0) | Z6: =IF(AND(OR(sel_Region="All",C6=sel_Region),OR(sel_Country="All",D6=sel_Country),OR(sel_Channel="All",E6=sel_Channel),OR(sel_Customer="All",F6=sel_Customer),OR(sel_Category="All",G6=sel_Category),AND(S6>=m_From,S6<=m_To)),1,0) | AA6: =IF(AND(OR(sel_Region="All",C6=sel_Region),OR(sel_Country="All",D6=sel_Country),OR(sel_Channel="All",E6=sel_Channel),OR(sel_Customer="All",F6=sel_Customer),OR(sel_Category="All",G6=sel_Category),OR(sel_Product="All",H6=sel_Product)),1,0)
A7: 00542 | B7: 46025 | C7: Southern Europe | D7: Spain | E7: Corporate | F7: Business | G7: Hiking | H7: Trail Boots | I7: 4 | J7: 143.67 | K7: 0.1 | L7: 81.22 | M7: =I7*J7*(1-K7) | N7: =I7*L7 | O7: =M7-N7 | P7: =IF(M7=0,0,O7/M7) | Q7: =YEAR(B7) | R7: ="Q"&ROUNDUP(MONTH(B7)/3,0) | S7: =MONTH(B7) | T7: =TEXT(B7,"mmm") | U7: =IF(AND(OR(sel_Region="All",C7=sel_Region),OR(sel_Country="All",D7=sel_Country),OR(sel_Channel="All",E7=sel_Channel),OR(sel_Customer="All",F7=sel_Customer),OR(sel_Category="All",G7=sel_Category),OR(sel_Product="All",H7=sel_Product),AND(S7>=m_From,S7<=m_To)),1,0) | V7: =IF(AND(OR(sel_Region="All",C7=sel_Region),OR(sel_Channel="All",E7=sel_Channel),OR(sel_Customer="All",F7=sel_Customer),OR(sel_Category="All",G7=sel_Category),OR(sel_Product="All",H7=sel_Product),AND(S7>=m_From,S7<=m_To)),1,0) | W7: =IF(AND(OR(sel_Region="All",C7=sel_Region),OR(sel_Country="All",D7=sel_Country),OR(sel_Customer="All",F7=sel_Customer),OR(sel_Category="All",G7=sel_Category),OR(sel_Product="All",H7=sel_Product),AND(S7>=m_From,S7<=m_To)),1,0) | X7: =IF(AND(OR(sel_Region="All",C7=sel_Region),OR(sel_Country="All",D7=sel_Country),OR(sel_Channel="All",E7=sel_Channel),OR(sel_Category="All",G7=sel_Category),OR(sel_Product="All",H7=sel_Product),AND(S7>=m_From,S7<=m_To)),1,0) | Y7: =IF(AND(OR(sel_Region="All",C7=sel_Region),OR(sel_Country="All",D7=sel_Country),OR(sel_Channel="All",E7=sel_Channel),OR(sel_Customer="All",F7=sel_Customer),OR(sel_Product="All",H7=sel_Product),AND(S7>=m_From,S7<=m_To)),1,0) | Z7: =IF(AND(OR(sel_Region="All",C7=sel_Region),OR(sel_Country="All",D7=sel_Country),OR(sel_Channel="All",E7=sel_Channel),OR(sel_Customer="All",F7=sel_Customer),OR(sel_Category="All",G7=sel_Category),AND(S7>=m_From,S7<=m_To)),1,0) | AA7: =IF(AND(OR(sel_Region="All",C7=sel_Region),OR(sel_Country="All",D7=sel_Country),OR(sel_Channel="All",E7=sel_Channel),OR(sel_Customer="All",F7=sel_Customer),OR(sel_Category="All",G7=sel_Category),OR(sel_Product="All",H7=sel_Product)),1,0)
A8: 02002 | B8: 46025 | C8: Southern Europe | D8: Spain | E8: Corporate | F8: Business | G8: Travel | H8: Insulated Bottle | I8: 3 | J8: 36.53 | K8: 0.15 | L8: 13.67 | M8: =I8*J8*(1-K8) | N8: =I8*L8 | O8: =M8-N8 | P8: =IF(M8=0,0,O8/M8) | Q8: =YEAR(B8) | R8: ="Q"&ROUNDUP(MONTH(B8)/3,0) | S8: =MONTH(B8) | T8: =TEXT(B8,"mmm") | U8: =IF(AND(OR(sel_Region="All",C8=sel_Region),OR(sel_Country="All",D8=sel_Country),OR(sel_Channel="All",E8=sel_Channel),OR(sel_Customer="All",F8=sel_Customer),OR(sel_Category="All",G8=sel_Category),OR(sel_Product="All",H8=sel_Product),AND(S8>=m_From,S8<=m_To)),1,0) | V8: =IF(AND(OR(sel_Region="All",C8=sel_Region),OR(sel_Channel="All",E8=sel_Channel),OR(sel_Customer="All",F8=sel_Customer),OR(sel_Category="All",G8=sel_Category),OR(sel_Product="All",H8=sel_Product),AND(S8>=m_From,S8<=m_To)),1,0) | W8: =IF(AND(OR(sel_Region="All",C8=sel_Region),OR(sel_Country="All",D8=sel_Country),OR(sel_Customer="All",F8=sel_Customer),OR(sel_Category="All",G8=sel_Category),OR(sel_Product="All",H8=sel_Product),AND(S8>=m_From,S8<=m_To)),1,0) | X8: =IF(AND(OR(sel_Region="All",C8=sel_Region),OR(sel_Country="All",D8=sel_Country),OR(sel_Channel="All",E8=sel_Channel),OR(sel_Category="All",G8=sel_Category),OR(sel_Product="All",H8=sel_Product),AND(S8>=m_From,S8<=m_To)),1,0) | Y8: =IF(AND(OR(sel_Region="All",C8=sel_Region),OR(sel_Country="All",D8=sel_Country),OR(sel_Channel="All",E8=sel_Channel),OR(sel_Customer="All",F8=sel_Customer),OR(sel_Product="All",H8=sel_Product),AND(S8>=m_From,S8<=m_To)),1,0) | Z8: =IF(AND(OR(sel_Region="All",C8=sel_Region),OR(sel_Country="All",D8=sel_Country),OR(sel_Channel="All",E8=sel_Channel),OR(sel_Customer="All",F8=sel_Customer),OR(sel_Category="All",G8=sel_Category),AND(S8>=m_From,S8<=m_To)),1,0) | AA8: =IF(AND(OR(sel_Region="All",C8=sel_Region),OR(sel_Country="All",D8=sel_Country),OR(sel_Channel="All",E8=sel_Channel),OR(sel_Customer="All",F8=sel_Customer),OR(sel_Category="All",G8=sel_Category),OR(sel_Product="All",H8=sel_Product)),1,0)
A9: 02005 | B9: 46025 | C9: Northern Europe | D9: Ireland | E9: Retail Partners | F9: New | G9: Travel | H9: Insulated Bottle | I9: 1 | J9: 35.34 | K9: 0 | L9: 13.37 | M9: =I9*J9*(1-K9) | N9: =I9*L9 | O9: =M9-N9 | P9: =IF(M9=0,0,O9/M9) | Q9: =YEAR(B9) | R9: ="Q"&ROUNDUP(MONTH(B9)/3,0) | S9: =MONTH(B9) | T9: =TEXT(B9,"mmm") | U9: =IF(AND(OR(sel_Region="All",C9=sel_Region),OR(sel_Country="All",D9=sel_Country),OR(sel_Channel="All",E9=sel_Channel),OR(sel_Customer="All",F9=sel_Customer),OR(sel_Category="All",G9=sel_Category),OR(sel_Product="All",H9=sel_Product),AND(S9>=m_From,S9<=m_To)),1,0) | V9: =IF(AND(OR(sel_Region="All",C9=sel_Region),OR(sel_Channel="All",E9=sel_Channel),OR(sel_Customer="All",F9=sel_Customer),OR(sel_Category="All",G9=sel_Category),OR(sel_Product="All",H9=sel_Product),AND(S9>=m_From,S9<=m_To)),1,0) | W9: =IF(AND(OR(sel_Region="All",C9=sel_Region),OR(sel_Country="All",D9=sel_Country),OR(sel_Customer="All",F9=sel_Customer),OR(sel_Category="All",G9=sel_Category),OR(sel_Product="All",H9=sel_Product),AND(S9>=m_From,S9<=m_To)),1,0) | X9: =IF(AND(OR(sel_Region="All",C9=sel_Region),OR(sel_Country="All",D9=sel_Country),OR(sel_Channel="All",E9=sel_Channel),OR(sel_Category="All",G9=sel_Category),OR(sel_Product="All",H9=sel_Product),AND(S9>=m_From,S9<=m_To)),1,0) | Y9: =IF(AND(OR(sel_Region="All",C9=sel_Region),OR(sel_Country="All",D9=sel_Country),OR(sel_Channel="All",E9=sel_Channel),OR(sel_Customer="All",F9=sel_Customer),OR(sel_Product="All",H9=sel_Product),AND(S9>=m_From,S9<=m_To)),1,0) | Z9: =IF(AND(OR(sel_Region="All",C9=sel_Region),OR(sel_Country="All",D9=sel_Country),OR(sel_Channel="All",E9=sel_Channel),OR(sel_Customer="All",F9=sel_Customer),OR(sel_Category="All",G9=sel_Category),AND(S9>=m_From,S9<=m_To)),1,0) | AA9: =IF(AND(OR(sel_Region="All",C9=sel_Region),OR(sel_Country="All",D9=sel_Country),OR(sel_Channel="All",E9=sel_Channel),OR(sel_Customer="All",F9=sel_Customer),OR(sel_Category="All",G9=sel_Category),OR(sel_Product="All",H9=sel_Product)),1,0)
A10: 02937 | B10: 46025 | C10: Western Europe | D10: Belgium | E10: Corporate | F10: Returning | G10: Cycling | H10: Trail Bike Light | I10: 8 | J10: 49.6 | K10: 0.1 | L10: 23.05 | M10: =I10*J10*(1-K10) | N10: =I10*L10 | O10: =M10-N10 | P10: =IF(M10=0,0,O10/M10) | Q10: =YEAR(B10) | R10: ="Q"&ROUNDUP(MONTH(B10)/3,0) | S10: =MONTH(B10) | T10: =TEXT(B10,"mmm") | U10: =IF(AND(OR(sel_Region="All",C10=sel_Region),OR(sel_Country="All",D10=sel_Country),OR(sel_Channel="All",E10=sel_Channel),OR(sel_Customer="All",F10=sel_Customer),OR(sel_Category="All",G10=sel_Category),OR(sel_Product="All",H10=sel_Product),AND(S10>=m_From,S10<=m_To)),1,0) | V10: =IF(AND(OR(sel_Region="All",C10=sel_Region),OR(sel_Channel="All",E10=sel_Channel),OR(sel_Customer="All",F10=sel_Customer),OR(sel_Category="All",G10=sel_Category),OR(sel_Product="All",H10=sel_Product),AND(S10>=m_From,S10<=m_To)),1,0) | W10: =IF(AND(OR(sel_Region="All",C10=sel_Region),OR(sel_Country="All",D10=sel_Country),OR(sel_Customer="All",F10=sel_Customer),OR(sel_Category="All",G10=sel_Category),OR(sel_Product="All",H10=sel_Product),AND(S10>=m_From,S10<=m_To)),1,0) | X10: =IF(AND(OR(sel_Region="All",C10=sel_Region),OR(sel_Country="All",D10=sel_Country),OR(sel_Channel="All",E10=sel_Channel),OR(sel_Category="All",G10=sel_Category),OR(sel_Product="All",H10=sel_Product),AND(S10>=m_From,S10<=m_To)),1,0) | Y10: =IF(AND(OR(sel_Region="All",C10=sel_Region),OR(sel_Country="All",D10=sel_Country),OR(sel_Channel="All",E10=sel_Channel),OR(sel_Customer="All",F10=sel_Customer),OR(sel_Product="All",H10=sel_Product),AND(S10>=m_From,S10<=m_To)),1,0) | Z10: =IF(AND(OR(sel_Region="All",C10=sel_Region),OR(sel_Country="All",D10=sel_Country),OR(sel_Channel="All",E10=sel_Channel),OR(sel_Customer="All",F10=sel_Customer),OR(sel_Category="All",G10=sel_Category),AND(S10>=m_From,S10<=m_To)),1,0) | AA10: =IF(AND(OR(sel_Region="All",C10=sel_Region),OR(sel_Country="All",D10=sel_Country),OR(sel_Channel="All",E10=sel_Channel),OR(sel_Customer="All",F10=sel_Customer),OR(sel_Category="All",G10=sel_Category),OR(sel_Product="All",H10=sel_Product)),1,0)
A11: 03326 | B11: 46025 | C11: Southern Europe | D11: Spain | E11: Retail Partners | F11: New | G11: Camping | H11: Alpine Tent 4P | I11: 2 | J11: 347.51 | K11: 0 | L11: 190.16 | M11: =I11*J11*(1-K11) | N11: =I11*L11 | O11: =M11-N11 | P11: =IF(M11=0,0,O11/M11) | Q11: =YEAR(B11) | R11: ="Q"&ROUNDUP(MONTH(B11)/3,0) | S11: =MONTH(B11) | T11: =TEXT(B11,"mmm") | U11: =IF(AND(OR(sel_Region="All",C11=sel_Region),OR(sel_Country="All",D11=sel_Country),OR(sel_Channel="All",E11=sel_Channel),OR(sel_Customer="All",F11=sel_Customer),OR(sel_Category="All",G11=sel_Category),OR(sel_Product="All",H11=sel_Product),AND(S11>=m_From,S11<=m_To)),1,0) | V11: =IF(AND(OR(sel_Region="All",C11=sel_Region),OR(sel_Channel="All",E11=sel_Channel),OR(sel_Customer="All",F11=sel_Customer),OR(sel_Category="All",G11=sel_Category),OR(sel_Product="All",H11=sel_Product),AND(S11>=m_From,S11<=m_To)),1,0) | W11: =IF(AND(OR(sel_Region="All",C11=sel_Region),OR(sel_Country="All",D11=sel_Country),OR(sel_Customer="All",F11=sel_Customer),OR(sel_Category="All",G11=sel_Category),OR(sel_Product="All",H11=sel_Product),AND(S11>=m_From,S11<=m_To)),1,0) | X11: =IF(AND(OR(sel_Region="All",C11=sel_Region),OR(sel_Country="All",D11=sel_Country),OR(sel_Channel="All",E11=sel_Channel),OR(sel_Category="All",G11=sel_Category),OR(sel_Product="All",H11=sel_Product),AND(S11>=m_From,S11<=m_To)),1,0) | Y11: =IF(AND(OR(sel_Region="All",C11=sel_Region),OR(sel_Country="All",D11=sel_Country),OR(sel_Channel="All",E11=sel_Channel),OR(sel_Customer="All",F11=sel_Customer),OR(sel_Product="All",H11=sel_Product),AND(S11>=m_From,S11<=m_To)),1,0) | Z11: =IF(AND(OR(sel_Region="All",C11=sel_Region),OR(sel_Country="All",D11=sel_Country),OR(sel_Channel="All",E11=sel_Channel),OR(sel_Customer="All",F11=sel_Customer),OR(sel_Category="All",G11=sel_Category),AND(S11>=m_From,S11<=m_To)),1,0) | AA11: =IF(AND(OR(sel_Region="All",C11=sel_Region),OR(sel_Country="All",D11=sel_Country),OR(sel_Channel="All",E11=sel_Channel),OR(sel_Customer="All",F11=sel_Customer),OR(sel_Category="All",G11=sel_Category),OR(sel_Product="All",H11=sel_Product)),1,0)
A12: 03863 | B12: 46025 | C12: Northern Europe | D12: Denmark | E12: Corporate | F12: Returning | G12: Cycling | H12: Compact Repair Kit | I12: 12 | J12: 41.22 | K12: 0.1 | L12: 16.64 | M12: =I12*J12*(1-K12) | N12: =I12*L12 | O12: =M12-N12 | P12: =IF(M12=0,0,O12/M12) | Q12: =YEAR(B12) | R12: ="Q"&ROUNDUP(MONTH(B12)/3,0) | S12: =MONTH(B12) | T12: =TEXT(B12,"mmm") | U12: =IF(AND(OR(sel_Region="All",C12=sel_Region),OR(sel_Country="All",D12=sel_Country),OR(sel_Channel="All",E12=sel_Channel),OR(sel_Customer="All",F12=sel_Customer),OR(sel_Category="All",G12=sel_Category),OR(sel_Product="All",H12=sel_Product),AND(S12>=m_From,S12<=m_To)),1,0) | V12: =IF(AND(OR(sel_Region="All",C12=sel_Region),OR(sel_Channel="All",E12=sel_Channel),OR(sel_Customer="All",F12=sel_Customer),OR(sel_Category="All",G12=sel_Category),OR(sel_Product="All",H12=sel_Product),AND(S12>=m_From,S12<=m_To)),1,0) | W12: =IF(AND(OR(sel_Region="All",C12=sel_Region),OR(sel_Country="All",D12=sel_Country),OR(sel_Customer="All",F12=sel_Customer),OR(sel_Category="All",G12=sel_Category),OR(sel_Product="All",H12=sel_Product),AND(S12>=m_From,S12<=m_To)),1,0) | X12: =IF(AND(OR(sel_Region="All",C12=sel_Region),OR(sel_Country="All",D12=sel_Country),OR(sel_Channel="All",E12=sel_Channel),OR(sel_Category="All",G12=sel_Category),OR(sel_Product="All",H12=sel_Product),AND(S12>=m_From,S12<=m_To)),1,0) | Y12: =IF(AND(OR(sel_Region="All",C12=sel_Region),OR(sel_Country="All",D12=sel_Country),OR(sel_Channel="All",E12=sel_Channel),OR(sel_Customer="All",F12=sel_Customer),OR(sel_Product="All",H12=sel_Product),AND(S12>=m_From,S12<=m_To)),1,0) | Z12: =IF(AND(OR(sel_Region="All",C12=sel_Region),OR(sel_Country="All",D12=sel_Country),OR(sel_Channel="All",E12=sel_Channel),OR(sel_Customer="All",F12=sel_Customer),OR(sel_Category="All",G12=sel_Category),AND(S12>=m_From,S12<=m_To)),1,0) | AA12: =IF(AND(OR(sel_Region="All",C12=sel_Region),OR(sel_Country="All",D12=sel_Country),OR(sel_Channel="All",E12=sel_Channel),OR(sel_Customer="All",F12=sel_Customer),OR(sel_Category="All",G12=sel_Category),OR(sel_Product="All",H12=sel_Product)),1,0)
A13: 04910 | B13: 46025 | C13: Northern Europe | D13: Ireland | E13: Retail Partners | F13: Business | G13: Camping | H13: Alpine Tent 4P | I13: 1 | J13: 332.18 | K13: 0 | L13: 195.33 | M13: =I13*J13*(1-K13) | N13: =I13*L13 | O13: =M13-N13 | P13: =IF(M13=0,0,O13/M13) | Q13: =YEAR(B13) | R13: ="Q"&ROUNDUP(MONTH(B13)/3,0) | S13: =MONTH(B13) | T13: =TEXT(B13,"mmm") | U13: =IF(AND(OR(sel_Region="All",C13=sel_Region),OR(sel_Country="All",D13=sel_Country),OR(sel_Channel="All",E13=sel_Channel),OR(sel_Customer="All",F13=sel_Customer),OR(sel_Category="All",G13=sel_Category),OR(sel_Product="All",H13=sel_Product),AND(S13>=m_From,S13<=m_To)),1,0) | V13: =IF(AND(OR(sel_Region="All",C13=sel_Region),OR(sel_Channel="All",E13=sel_Channel),OR(sel_Customer="All",F13=sel_Customer),OR(sel_Category="All",G13=sel_Category),OR(sel_Product="All",H13=sel_Product),AND(S13>=m_From,S13<=m_To)),1,0) | W13: =IF(AND(OR(sel_Region="All",C13=sel_Region),OR(sel_Country="All",D13=sel_Country),OR(sel_Customer="All",F13=sel_Customer),OR(sel_Category="All",G13=sel_Category),OR(sel_Product="All",H13=sel_Product),AND(S13>=m_From,S13<=m_To)),1,0) | X13: =IF(AND(OR(sel_Region="All",C13=sel_Region),OR(sel_Country="All",D13=sel_Country),OR(sel_Channel="All",E13=sel_Channel),OR(sel_Category="All",G13=sel_Category),OR(sel_Product="All",H13=sel_Product),AND(S13>=m_From,S13<=m_To)),1,0) | Y13: =IF(AND(OR(sel_Region="All",C13=sel_Region),OR(sel_Country="All",D13=sel_Country),OR(sel_Channel="All",E13=sel_Channel),OR(sel_Customer="All",F13=sel_Customer),OR(sel_Product="All",H13=sel_Product),AND(S13>=m_From,S13<=m_To)),1,0) | Z13: =IF(AND(OR(sel_Region="All",C13=sel_Region),OR(sel_Country="All",D13=sel_Country),OR(sel_Channel="All",E13=sel_Channel),OR(sel_Customer="All",F13=sel_Customer),OR(sel_Category="All",G13=sel_Category),AND(S13>=m_From,S13<=m_To)),1,0) | AA13: =IF(AND(OR(sel_Region="All",C13=sel_Region),OR(sel_Country="All",D13=sel_Country),OR(sel_Channel="All",E13=sel_Channel),OR(sel_Customer="All",F13=sel_Customer),OR(sel_Category="All",G13=sel_Category),OR(sel_Product="All",H13=sel_Product)),1,0)
A14: 05188 | B14: 46025 | C14: Central Europe | D14: Austria | E14: Marketplace | F14: Returning | G14: Cycling | H14: Trail Bike Light | I14: 1 | J14: 49.71 | K14: 0 | L14: 23.15 | M14: =I14*J14*(1-K14) | N14: =I14*L14 | O14: =M14-N14 | P14: =IF(M14=0,0,O14/M14) | Q14: =YEAR(B14) | R14: ="Q"&ROUNDUP(MONTH(B14)/3,0) | S14: =MONTH(B14) | T14: =TEXT(B14,"mmm") | U14: =IF(AND(OR(sel_Region="All",C14=sel_Region),OR(sel_Country="All",D14=sel_Country),OR(sel_Channel="All",E14=sel_Channel),OR(sel_Customer="All",F14=sel_Customer),OR(sel_Category="All",G14=sel_Category),OR(sel_Product="All",H14=sel_Product),AND(S14>=m_From,S14<=m_To)),1,0) | V14: =IF(AND(OR(sel_Region="All",C14=sel_Region),OR(sel_Channel="All",E14=sel_Channel),OR(sel_Customer="All",F14=sel_Customer),OR(sel_Category="All",G14=sel_Category),OR(sel_Product="All",H14=sel_Product),AND(S14>=m_From,S14<=m_To)),1,0) | W14: =IF(AND(OR(sel_Region="All",C14=sel_Region),OR(sel_Country="All",D14=sel_Country),OR(sel_Customer="All",F14=sel_Customer),OR(sel_Category="All",G14=sel_Category),OR(sel_Product="All",H14=sel_Product),AND(S14>=m_From,S14<=m_To)),1,0) | X14: =IF(AND(OR(sel_Region="All",C14=sel_Region),OR(sel_Country="All",D14=sel_Country),OR(sel_Channel="All",E14=sel_Channel),OR(sel_Category="All",G14=sel_Category),OR(sel_Product="All",H14=sel_Product),AND(S14>=m_From,S14<=m_To)),1,0) | Y14: =IF(AND(OR(sel_Region="All",C14=sel_Region),OR(sel_Country="All",D14=sel_Country),OR(sel_Channel="All",E14=sel_Channel),OR(sel_Customer="All",F14=sel_Customer),OR(sel_Product="All",H14=sel_Product),AND(S14>=m_From,S14<=m_To)),1,0) | Z14: =IF(AND(OR(sel_Region="All",C14=sel_Region),OR(sel_Country="All",D14=sel_Country),OR(sel_Channel="All",E14=sel_Channel),OR(sel_Customer="All",F14=sel_Customer),OR(sel_Category="All",G14=sel_Category),AND(S14>=m_From,S14<=m_To)),1,0) | AA14: =IF(AND(OR(sel_Region="All",C14=sel_Region),OR(sel_Country="All",D14=sel_Country),OR(sel_Channel="All",E14=sel_Channel),OR(sel_Customer="All",F14=sel_Customer),OR(sel_Category="All",G14=sel_Category),OR(sel_Product="All",H14=sel_Product)),1,0)
A15: 00845 | B15: 46026 | C15: Northern Europe | D15: Ireland | E15: Online Store | F15: New | G15: Camping | H15: Trail Tent 2P | I15: 2 | J15: 194.35 | K15: 0 | L15: 104.22 | M15: =I15*J15*(1-K15) | N15: =I15*L15 | O15: =M15-N15 | P15: =IF(M15=0,0,O15/M15) | Q15: =YEAR(B15) | R15: ="Q"&ROUNDUP(MONTH(B15)/3,0) | S15: =MONTH(B15) | T15: =TEXT(B15,"mmm") | U15: =IF(AND(OR(sel_Region="All",C15=sel_Region),OR(sel_Country="All",D15=sel_Country),OR(sel_Channel="All",E15=sel_Channel),OR(sel_Customer="All",F15=sel_Customer),OR(sel_Category="All",G15=sel_Category),OR(sel_Product="All",H15=sel_Product),AND(S15>=m_From,S15<=m_To)),1,0) | V15: =IF(AND(OR(sel_Region="All",C15=sel_Region),OR(sel_Channel="All",E15=sel_Channel),OR(sel_Customer="All",F15=sel_Customer),OR(sel_Category="All",G15=sel_Category),OR(sel_Product="All",H15=sel_Product),AND(S15>=m_From,S15<=m_To)),1,0) | W15: =IF(AND(OR(sel_Region="All",C15=sel_Region),OR(sel_Country="All",D15=sel_Country),OR(sel_Customer="All",F15=sel_Customer),OR(sel_Category="All",G15=sel_Category),OR(sel_Product="All",H15=sel_Product),AND(S15>=m_From,S15<=m_To)),1,0) | X15: =IF(AND(OR(sel_Region="All",C15=sel_Region),OR(sel_Country="All",D15=sel_Country),OR(sel_Channel="All",E15=sel_Channel),OR(sel_Category="All",G15=sel_Category),OR(sel_Product="All",H15=sel_Product),AND(S15>=m_From,S15<=m_To)),1,0) | Y15: =IF(AND(OR(sel_Region="All",C15=sel_Region),OR(sel_Country="All",D15=sel_Country),OR(sel_Channel="All",E15=sel_Channel),OR(sel_Customer="All",F15=sel_Customer),OR(sel_Product="All",H15=sel_Product),AND(S15>=m_From,S15<=m_To)),1,0) | Z15: =IF(AND(OR(sel_Region="All",C15=sel_Region),OR(sel_Country="All",D15=sel_Country),OR(sel_Channel="All",E15=sel_Channel),OR(sel_Customer="All",F15=sel_Customer),OR(sel_Category="All",G15=sel_Category),AND(S15>=m_From,S15<=m_To)),1,0) | AA15: =IF(AND(OR(sel_Region="All",C15=sel_Region),OR(sel_Country="All",D15=sel_Country),OR(sel_Channel="All",E15=sel_Channel),OR(sel_Customer="All",F15=sel_Customer),OR(sel_Category="All",G15=sel_Category),OR(sel_Product="All",H15=sel_Product)),1,0)
... A2710: 05135 | B2710: 46386 | C2710: Northern Europe | D2710: Finland | E2710: Online Store | F2710: New | G2710: Cycling | H2710: Trail Bike Light | I2710: 5 | J2710: 51.78 | K2710: 0.15 | L2710: 22.37 | M2710: =I2710*J2710*(1-K2710) | N2710: =I2710*L2710 | O2710: =M2710-N2710 | P2710: =IF(M2710=0,0,O2710/M2710) | Q2710: =YEAR(B2710) | R2710: ="Q"&ROUNDUP(MONTH(B2710)/3,0) | S2710: =MONTH(B2710) | T2710: =TEXT(B2710,"mmm") | U2710: =IF(AND(OR(sel_Region="All",C2710=sel_Region),OR(sel_Country="All",D2710=sel_Country),OR(sel_Channel="All",E2710=sel_Channel),OR(sel_Customer="All",F2710=sel_Customer),OR(sel_Category="All",G2710=sel_Category),OR(sel_Product="All",H2710=sel_Product),AND(S2710>=m_From,S2710<=m_To)),1,0) | V2710: =IF(AND(OR(sel_Region="All",C2710=sel_Region),OR(sel_Channel="All",E2710=sel_Channel),OR(sel_Customer="All",F2710=sel_Customer),OR(sel_Category="All",G2710=sel_Category),OR(sel_Product="All",H2710=sel_Product),AND(S2710>=m_From,S2710<=m_To)),1,0) | W2710: =IF(AND(OR(sel_Region="All",C2710=sel_Region),OR(sel_Country="All",D2710=sel_Country),OR(sel_Customer="All",F2710=sel_Customer),OR(sel_Category="All",G2710=sel_Category),OR(sel_Product="All",H2710=sel_Product),AND(S2710>=m_From,S2710<=m_To)),1,0) | X2710: =IF(AND(OR(sel_Region="All",C2710=sel_Region),OR(sel_Country="All",D2710=sel_Country),OR(sel_Channel="All",E2710=sel_Channel),OR(sel_Category="All",G2710=sel_Category),OR(sel_Product="All",H2710=sel_Product),AND(S2710>=m_From,S2710<=m_To)),1,0) | Y2710: =IF(AND(OR(sel_Region="All",C2710=sel_Region),OR(sel_Country="All",D2710=sel_Country),OR(sel_Channel="All",E2710=sel_Channel),OR(sel_Customer="All",F2710=sel_Customer),OR(sel_Product="All",H2710=sel_Product),AND(S2710>=m_From,S2710<=m_To)),1,0) | Z2710: =IF(AND(OR(sel_Region="All",C2710=sel_Region),OR(sel_Country="All",D2710=sel_Country),OR(sel_Channel="All",E2710=sel_Channel),OR(sel_Customer="All",F2710=sel_Customer),OR(sel_Category="All",G2710=sel_Category),AND(S2710>=m_From,S2710<=m_To)),1,0) | AA2710: =IF(AND(OR(sel_Region="All",C2710=sel_Region),OR(sel_Country="All",D2710=sel_Country),OR(sel_Channel="All",E2710=sel_Channel),OR(sel_Customer="All",F2710=sel_Customer),OR(sel_Category="All",G2710=sel_Category),OR(sel_Product="All",H2710=sel_Product)),1,0)

Sheet Lists
A1: Lists (feed the dashboard dropdowns - do not edit)
A3: Region | B3: Sales Channel | C3: Customer Type | D3: Month | E3: Category | F3: Country | G3: Product
A4: All | B4: All | C4: All | D4: Jan | E4: All | F4: All | G4: All
A5: Central Europe | B5: Corporate | C5: Business | D5: Feb | E5: Camping | F5: Austria | G5: Alpine Tent 4P
A6: Northern Europe | B6: Marketplace | C6: New | D6: Mar | E6: Cycling | F6: Belgium | G6: Carry-On Duffel
A7: Southern Europe | B7: Online Store | C7: Returning | D7: Apr | E7: Fitness | F7: Czechia | G7: Commuter Helmet
A8: Western Europe | B8: Retail Partners | D8: May | E8: Hiking | F8: Denmark | G8: Compact Repair Kit
D9: Jun | E9: Travel | F9: Finland | G9: Compact Sleeping Bag
D10: Jul | F10: France | G10: Cycling Pack 12L
D11: Aug | F11: Germany | G11: Hiking Daypack 20L
D12: Sep | F12: Ireland | G12: Insulated Bottle
D13: Oct | F13: Italy | G13: Packing Cube Set
D14: Nov | F14: Netherlands | G14: Portable Camp Stove
D15: Dec | F15: Norway | G15: Recovery Roller
F16: Poland | G16: Resistance Band Set
F17: Portugal | G17: Summit Backpack 45L
F18: Spain | G18: Trail Bike Light
F19: Sweden | G19: Trail Boots
F20: Switzerland | G20: Trail Tent 2P
F21: United Kingdom | G21: Training Mat
G22: Travel Backpack 35L
G23: Trekking Poles
G24: Weighted Vest

Sheet Guide
B1: Guide | E1: Dashboard | F1: Analysis | G1: Data | H1: Guide
B3: How to use | C3: Use the 8 orange dropdowns on the Dashboard (Region, Country, Channel, Customer, Category, Product, From/To month). Everything recalculates instantly. Set a dropdown back to "All" to clear it.
B5: Cross-filtering | C5: Every chart ignores its OWN filter and shows the selected bar in colour while other bars turn grey (Power BI style); all other visuals, KPIs and highlights filter to the selection. Without macros you choose the item in the dropdown; with the macro in CrossFilter_Macro.txt you click the bar, month or map tile directly. Clicking it again clears it. Clicking the ORDERS SHOWN box resets all filters.
B7: Navigation | C7: Use the Dashboard | Analysis | Data | Guide buttons at the top of every sheet.
B9: Data sheet | C9: Table "SalesData" - 2,707 orders. Revenue, COGS, Gross Profit, Margin, Year, Quarter and Month are formulas. Column U "In Filter" = 1 when a row passes every filter; columns V:AA are the same test with one filter left out (used so a chart can still show the bars that are not selected).
B11: To add data | C11: Paste new rows under the table, extend the formulas in M:AA, and widen the ranges (rows 4 to 2710).
B13: Analysis sheet | C13: All calculations: KPIs, monthly trend and sorted blocks for category, channel, customer type, country and top-5 products. Highlights strip is in G3:H9.
B15: Definitions | C15: Revenue = Units x Unit Price x (1 - Discount). COGS = Units x Unit Cost. Gross Profit = Revenue - COGS. Avg Order Value = Revenue / Orders. Avg Unit Price = Revenue / Units.
B17: Protection | C17: The Dashboard sheet is protected (no password); only orange filter cells are editable. To edit the layout: Review > Unprotect Sheet. The macro re-protects it in a chart-friendly way each time the file opens.
B19: Limits | C19: Dropdowns/macro clicks replace slicers and the timeline; cells replace pivot tables and the filled map. Chart-click filtering needs the macro and desktop Excel (Windows or Mac); it does not run in Excel for the web or mobile.
